Workbook

Sheet Sheet1
A1: 贵阳公共交通（集团）有限公司运营生产月报（客运量）
A2: 填报单位：小河分公司
A3: 单位名称 | C3: 投币客运量 | D3: 刷卡客运量 | T3: 市场客运量 | U3: 总计
D4: 九折卡客运量 | E4: 银联卡客运量 | F4: 季票客运量 | J4: 减、免卡客运量 | S4: 刷卡累计
F5: 成人季票 | G5: 学生季票 | H5: 息烽季票 | I5: 小计 | J5: 老年卡 | K5: 残疾人卡 | L5: 退休职工卡 | M5: 职工卡 | N5: 退伍军人A | O5: 退伍军人B | P5: 义务监督卡 | Q5: 综合卡人次 | R5: 小计
A6: 小河分公司合计 | C6: =SUM(C7:C87) -> 736626 | D6: =SUM(D7:D87) -> 4528641 | E6: =SUM(E7:E87) -> 184193 | F6: =SUM(F7:F87) -> 756 | G6: =SUM(G7:G87) -> 237847 | H6: =SUM(H7:H87) -> 0 | I6: =SUM(I7:I87) -> 238603 | J6: =SUM(J7:J87) -> 1634600 | ... U6: =SUM(U7:U87) -> 8035120
A7: 一车队 | B7: 5路 | C7: 17980 | D7: 135807 | E7: 6220 | F7: 9 | G7: 6933 | H7: 0 | I7: =SUM(F7:H7) -> 6942 | J7: 52292 | K7: 9283 | L7: 3625 | M7: 1875 | N7: 6859 | O7: 0 | P7: 146 | Q7: 104 | R7: =SUM(J7:Q7) -> 74184 | S7: =R7+I7+E7+D7 -> 223153 | T7: =IFERROR(VLOOKUP(B7,[1]月分析表!$A$9:$AT$120,44,0),0)+IFERROR(VLOOKUP(B7,[1]月分析表!$A$9:$AU$120,46,0),0) -> 305 | U7: =S7+C7+T7 -> 241438
B8: 47路 | C8: 20497 | D8: 117514 | E8: 3553 | F8: 0 | G8: 7865 | H8: 0 | I8: =SUM(F8:H8) -> 7865 | J8: 31861 | K8: 6139 | L8: 1523 | M8: 1038 | N8: 5936 | O8: 0 | P8: 138 | Q8: 38 | R8: =SUM(J8:Q8) -> 46673 | S8: =R8+I8+E8+D8 -> 175605 | T8: =IFERROR(VLOOKUP(B8,[1]月分析表!$A$9:$AT$120,44,0),0)+IFERROR(VLOOKUP(B8,[1]月分析表!$A$9:$AU$120,46,0),0) -> 63 | U8: =S8+C8+T8 -> 196165
B9: 52路 | C9: 8795 | D9: 78004 | E9: 4462 | F9: 2 | G9: 2390 | H9: 0 | I9: =SUM(F9:H9) -> 2392 | J9: 51183 | K9: 6857 | L9: 2826 | M9: 1017 | N9: 3940 | O9: 0 | P9: 155 | Q9: 52 | R9: =SUM(J9:Q9) -> 66030 | S9: =R9+I9+E9+D9 -> 150888 | T9: =IFERROR(VLOOKUP(B9,[1]月分析表!$A$9:$AT$120,44,0),0)+IFERROR(VLOOKUP(B9,[1]月分析表!$A$9:$AU$120,46,0),0) -> 7746 | U9: =S9+C9+T9 -> 167429
B10: 69路 | C10: 11338 | D10: 88403 | E10: 2467 | F10: 3 | G10: 5269 | H10: 0 | I10: =SUM(F10:H10) -> 5272 | J10: 18957 | K10: 3772 | L10: 1108 | M10: 610 | N10: 4465 | O10: 0 | P10: 43 | Q10: 15 | R10: =SUM(J10:Q10) -> 28970 | S10: =R10+I10+E10+D10 -> 125112 | T10: =IFERROR(VLOOKUP(B10,[1]月分析表!$A$9:$AT$120,44,0),0)+IFERROR(VLOOKUP(B10,[1]月分析表!$A$9:$AU$120,46,0),0) -> 0 | U10: =S10+C10+T10 -> 136450
B11: 75路 | C11: 10807 | D11: 98497 | E11: 4258 | F11: 3 | G11: 2797 | H11: 0 | I11: =SUM(F11:H11) -> 2800 | J11: 30475 | K11: 5885 | L11: 2606 | M11: 1077 | N11: 4975 | O11: 0 | P11: 127 | Q11: 94 | R11: =SUM(J11:Q11) -> 45239 | S11: =R11+I11+E11+D11 -> 150794 | T11: =IFERROR(VLOOKUP(B11,[1]月分析表!$A$9:$AT$120,44,0),0)+IFERROR(VLOOKUP(B11,[1]月分析表!$A$9:$AU$120,46,0),0) -> 1843 | U11: =S11+C11+T11 -> 163444
B12: 202路 | C12: 9346 | D12: 75631 | E12: 2347 | F12: 1 | G12: 3340 | H12: 0 | I12: =SUM(F12:H12) -> 3341 | J12: 19061 | K12: 4577 | L12: 1537 | M12: 977 | N12: 3820 | O12: 0 | P12: 63 | Q12: 42 | R12: =SUM(J12:Q12) -> 30077 | S12: =R12+I12+E12+D12 -> 111396 | T12: =IFERROR(VLOOKUP(B12,[1]月分析表!$A$9:$AT$120,44,0),0)+IFERROR(VLOOKUP(B12,[1]月分析表!$A$9:$AU$120,46,0),0) -> 0 | U12: =S12+C12+T12 -> 120742
B13: 254路 | C13: 2637 | D13: 11787 | E13: 344 | F13: 0 | G13: 982 | H13: 0 | I13: =SUM(F13:H13) -> 982 | J13: 2930 | K13: 673 | L13: 63 | M13: 128 | N13: 595 | O13: 0 | P13: 1 | Q13: 2 | R13: =SUM(J13:Q13) -> 4392 | S13: =R13+I13+E13+D13 -> 17505 | T13: =IFERROR(VLOOKUP(B13,[1]月分析表!$A$9:$AT$120,44,0),0)+IFERROR(VLOOKUP(B13,[1]月分析表!$A$9:$AU$120,46,0),0) -> 0 | U13: =S13+C13+T13 -> 20142
B14: 308路 | C14: 9525 | D14: 96488 | E14: 2368 | F14: 1 | G14: 3585 | H14: 0 | I14: =SUM(F14:H14) -> 3586 | J14: 21137 | K14: 3825 | L14: 982 | M14: 574 | N14: 4873 | O14: 0 | P14: 33 | Q14: 19 | R14: =SUM(J14:Q14) -> 31443 | S14: =R14+I14+E14+D14 -> 133885 | T14: =IFERROR(VLOOKUP(B14,[1]月分析表!$A$9:$AT$120,44,0),0)+IFERROR(VLOOKUP(B14,[1]月分析表!$A$9:$AU$120,46,0),0) -> 0 | U14: =S14+C14+T14 -> 143410
B15: 325路 | C15: 2457 | D15: 5802 | E15: 185 | F15: 1 | G15: 1464 | H15: 0 | I15: =SUM(F15:H15) -> 1465 | J15: 2736 | K15: 358 | L15: 54 | M15: 71 | N15: 293 | O15: 0 | P15: 0 | Q15: 0 | R15: =SUM(J15:Q15) -> 3512 | S15: =R15+I15+E15+D15 -> 10964 | T15: =IFERROR(VLOOKUP(B15,[1]月分析表!$A$9:$AT$120,44,0),0)+IFERROR(VLOOKUP(B15,[1]月分析表!$A$9:$AU$120,46,0),0) -> 0 | U15: =S15+C15+T15 -> 13421
B16: 612路 | C16: 3871 | D16: 15231 | E16: 899 | F16: 0 | G16: 5056 | H16: 0 | I16: =SUM(F16:H16) -> 5056 | J16: 9304 | K16: 2768 | L16: 405 | M16: 195 | N16: 770 | O16: 0 | P16: 39 | Q16: 32 | R16: =SUM(J16:Q16) -> 13513 | S16: =R16+I16+E16+D16 -> 34699 | T16: =IFERROR(VLOOKUP(B16,[1]月分析表!$A$9:$AT$120,44,0),0)+IFERROR(VLOOKUP(B16,[1]月分析表!$A$9:$AU$120,46,0),0) -> 0 | U16: =S16+C16+T16 -> 38570
B17: 20207路 | C17: 740 | D17: 2294 | E17: 93 | F17: 0 | G17: 36 | H17: 0 | I17: =SUM(F17:H17) -> 36 | J17: 997 | K17: 179 | L17: 30 | M17: 17 | N17: 116 | O17: 0 | P17: 0 | Q17: 2 | R17: =SUM(J17:Q17) -> 1341 | S17: =R17+I17+E17+D17 -> 3764 | T17: =IFERROR(VLOOKUP(B17,[1]月分析表!$A$9:$AT$120,44,0),0)+IFERROR(VLOOKUP(B17,[1]月分析表!$A$9:$AU$120,46,0),0) -> 0 | U17: =S17+C17+T17 -> 4504
A18: 二车队 | B18: 204路 | C18: 30079 | D18: 131243 | E18: 6698 | F18: 3 | G18: 8478 | H18: 0 | I18: =SUM(F18:H18) -> 8481 | J18: 62303 | K18: 8642 | L18: 1539 | M18: 1375 | N18: 6629 | O18: 0 | P18: 43 | Q18: 46 | R18: =SUM(J18:Q18) -> 80577 | S18: =R18+I18+E18+D18 -> 226999 | T18: =IFERROR(VLOOKUP(B18,[1]月分析表!$A$9:$AT$120,44,0),0)+IFERROR(VLOOKUP(B18,[1]月分析表!$A$9:$AU$120,46,0),0) -> 591 | U18: =S18+C18+T18 -> 257669
B19: 207路 | C19: 14444 | D19: 128668 | E19: 2393 | F19: 1 | G19: 1696 | H19: 0 | I19: =SUM(F19:H19) -> 1697 | J19: 17565 | K19: 3903 | L19: 1095 | M19: 682 | N19: 6498 | O19: 0 | P19: 33 | Q19: 12 | R19: =SUM(J19:Q19) -> 29788 | S19: =R19+I19+E19+D19 -> 162546 | T19: =IFERROR(VLOOKUP(B19,[1]月分析表!$A$9:$AT$120,44,0),0)+IFERROR(VLOOKUP(B19,[1]月分析表!$A$9:$AU$120,46,0),0) -> 186 | U19: =S19+C19+T19 -> 177176
B20: 248路 | C20: 57079 | D20: 225621 | E20: 10387 | F20: 6 | G20: 11832 | H20: 0 | I20: =SUM(F20:H20) -> 11838 | J20: 97597 | K20: 16367 | L20: 5707 | M20: 3221 | N20: 11396 | O20: 0 | P20: 171 | Q20: 96 | R20: =SUM(J20:Q20) -> 134555 | S20: =R20+I20+E20+D20 -> 382401 | T20: =IFERROR(VLOOKUP(B20,[1]月分析表!$A$9:$AT$120,44,0),0)+IFERROR(VLOOKUP(B20,[1]月分析表!$A$9:$AU$120,46,0),0) -> 5590 | U20: =S20+C20+T20 -> 445070
B21: 255路 | C21: 19143 | D21: 119167 | E21: 2178 | F21: 20 | G21: 1664 | H21: 0 | I21: =SUM(F21:H21) -> 1684 | J21: 12618 | K21: 4254 | L21: 847 | M21: 465 | N21: 6019 | O21: 0 | P21: 30 | Q21: 30 | R21: =SUM(J21:Q21) -> 24263 | S21: =R21+I21+E21+D21 -> 147292 | T21: =IFERROR(VLOOKUP(B21,[1]月分析表!$A$9:$AT$120,44,0),0)+IFERROR(VLOOKUP(B21,[1]月分析表!$A$9:$AU$120,46,0),0) -> 191 | U21: =S21+C21+T21 -> 166626
B22: 806路 | C22: 289 | D22: 7399 | E22: 71 | F22: 0 | G22: 50 | H22: 0 | I22: =SUM(F22:H22) -> 50 | J22: 877 | K22: 215 | L22: 55 | M22: 45 | N22: 374 | O22: 0 | P22: 3 | Q22: 2 | R22: =SUM(J22:Q22) -> 1571 | S22: =R22+I22+E22+D22 -> 9091 | T22: =IFERROR(VLOOKUP(B22,[1]月分析表!$A$9:$AT$120,44,0),0)+IFERROR(VLOOKUP(B22,[1]月分析表!$A$9:$AU$120,46,0),0) -> 3313 | U22: =S22+C22+T22 -> 12693
B23: 808路 | C23: 623 | D23: 8266 | E23: 84 | F23: 0 | G23: 51 | H23: 0 | I23: =SUM(F23:H23) -> 51 | J23: 842 | K23: 141 | L23: 71 | M23: 70 | N23: 418 | O23: 0 | P23: 6 | Q23: 1 | R23: =SUM(J23:Q23) -> 1549 | S23: =R23+I23+E23+D23 -> 9950 | T23: =IFERROR(VLOOKUP(B23,[1]月分析表!$A$9:$AT$120,44,0),0)+IFERROR(VLOOKUP(B23,[1]月分析表!$A$9:$AU$120,46,0),0) -> 0 | U23: =S23+C23+T23 -> 10573
B24: 809路 | C24: 1696 | D24: 2350 | E24: 12 | F24: 0 | G24: 0 | H24: 0 | I24: =SUM(F24:H24) -> 0 | J24: 0 | K24: 0 | L24: 0 | M24: 0 | N24: 0 | O24: 0 | P24: 0 | Q24: 0 | R24: =SUM(J24:Q24) -> 0 | S24: =R24+I24+E24+D24 -> 2362 | T24: =IFERROR(VLOOKUP(B24,[1]月分析表!$A$9:$AT$78,44,0),0)+IFERROR(VLOOKUP(B24,[1]月分析表!$A$9:$AU$78,46,0),0)+S24+C24 -> 4058 | U24: =T24 -> 4058
B25: B267路 | C25: 2558 | D25: 12755 | E25: 333 | F25: 0 | G25: 132 | H25: 0 | I25: =SUM(F25:H25) -> 132 | J25: 1639 | K25: 590 | L25: 95 | M25: 102 | N25: 645 | O25: 0 | P25: 3 | Q25: 5 | R25: =SUM(J25:Q25) -> 3079 | S25: =R25+I25+E25+D25 -> 16299 | T25: =IFERROR(VLOOKUP(B25,[1]月分析表!$A$9:$AT$120,44,0),0)+IFERROR(VLOOKUP(B25,[1]月分析表!$A$9:$AU$120,46,0),0) -> 0 | U25: =S25+C25+T25 -> 18857
B26: 10248路 | C26: 26226 | D26: 119991 | E26: 4814 | F26: 0 | G26: 3392 | H26: 0 | I26: =SUM(F26:H26) -> 3392 | J26: 42001 | K26: 6826 | L26: 2362 | M26: 1320 | N26: 6061 | O26: 0 | P26: 84 | Q26: 26 | R26: =SUM(J26:Q26) -> 58680 | S26: =R26+I26+E26+D26 -> 186877 | T26: =IFERROR(VLOOKUP(B26,[1]月分析表!$A$9:$AT$120,44,0),0)+IFERROR(VLOOKUP(B26,[1]月分析表!$A$9:$AU$120,46,0),0) -> 1713 | U26: =S26+C26+T26 -> 214816
A27: 三车队 | B27: 9路 | C27: 24466 | D27: 179519 | E27: 7458 | F27: 86 | G27: 7990 | H27: 0 | I27: =SUM(F27:H27) -> 8076 | J27: 69019 | K27: 10419 | L27: 2481 | M27: 1531 | N27: 9068 | O27: 0 | P27: 118 | Q27: 116 | R27: =SUM(J27:Q27) -> 92752 | S27: =R27+I27+E27+D27 -> 287805 | T27: =IFERROR(VLOOKUP(B27,[1]月分析表!$A$9:$AT$120,44,0),0)+IFERROR(VLOOKUP(B27,[1]月分析表!$A$9:$AU$120,46,0),0) -> 47 | U27: =S27+C27+T27 -> 312318
B28: 11路 | C28: 21836 | D28: 142382 | E28: 5798 | F28: 1 | G28: 7719 | H28: 0 | I28: =SUM(F28:H28) -> 7720 | J28: 55602 | K28: 9784 | L28: 2307 | M28: 1063 | N28: 7191 | O28: 0 | P28: 134 | Q28: 100 | R28: =SUM(J28:Q28) -> 76181 | S28: =R28+I28+E28+D28 -> 232081 | T28: =IFERROR(VLOOKUP(B28,[1]月分析表!$A$9:$AT$120,44,0),0)+IFERROR(VLOOKUP(B28,[1]月分析表!$A$9:$AU$120,46,0),0) -> 2962 | U28: =S28+C28+T28 -> 256879
B29: 13路 | C29: 25939 | D29: 110789 | E29: 5444 | F29: 0 | G29: 11133 | H29: 0 | I29: =SUM(F29:H29) -> 11133 | J29: 59798 | K29: 8871 | L29: 2482 | M29: 1181 | N29: 5596 | O29: 0 | P29: 81 | Q29: 47 | R29: =SUM(J29:Q29) -> 78056 | S29: =R29+I29+E29+D29 -> 205422 | T29: =IFERROR(VLOOKUP(B29,[1]月分析表!$A$9:$AT$120,44,0),0)+IFERROR(VLOOKUP(B29,[1]月分析表!$A$9:$AU$120,46,0),0) -> 693 | U29: =S29+C29+T29 -> 232054
B30: 43路 | C30: 23993 | D30: 61859 | E30: 2528 | F30: 1 | G30: 4026 | H30: 0 | I30: =SUM(F30:H30) -> 4027 | J30: 29074 | K30: 4530 | L30: 721 | M30: 789 | N30: 3125 | O30: 0 | P30: 15 | Q30: 36 | R30: =SUM(J30:Q30) -> 38290 | S30: =R30+I30+E30+D30 -> 106704 | T30: =IFERROR(VLOOKUP(B30,[1]月分析表!$A$9:$AT$120,44,0),0)+IFERROR(VLOOKUP(B30,[1]月分析表!$A$9:$AU$120,46,0),0) -> 323 | U30: =S30+C30+T30 -> 131020
B31: 53路 | C31: 6234 | D31: 29965 | E31: 1090 | F31: 0 | G31: 2790 | H31: 0 | I31: =SUM(F31:H31) -> 2790 | J31: 8363 | K31: 1936 | L31: 292 | M31: 343 | N31: 1513 | O31: 0 | P31: 15 | Q31: 4 | R31: =SUM(J31:Q31) -> 12466 | S31: =R31+I31+E31+D31 -> 46311 | T31: =IFERROR(VLOOKUP(B31,[1]月分析表!$A$9:$AT$120,44,0),0)+IFERROR(VLOOKUP(B31,[1]月分析表!$A$9:$AU$120,46,0),0) -> 1166 | U31: =S31+C31+T31 -> 53711
B32: 327路 | C32: 2846 | D32: 5506 | E32: 250 | F32: 0 | G32: 93 | H32: 0 | I32: =SUM(F32:H32) -> 93 | J32: 3155 | K32: 426 | L32: 42 | M32: 50 | N32: 278 | O32: 0 | P32: 0 | Q32: 2 | R32: =SUM(J32:Q32) -> 3953 | S32: =R32+I32+E32+D32 -> 9802 | T32: =IFERROR(VLOOKUP(B32,[1]月分析表!$A$9:$AT$120,44,0),0)+IFERROR(VLOOKUP(B32,[1]月分析表!$A$9:$AU$120,46,0),0) -> 0 | U32: =S32+C32+T32 -> 12648
B33: 609路 | C33: 2854 | D33: 23698 | E33: 1292 | F33: 0 | G33: 2146 | H33: 0 | I33: =SUM(F33:H33) -> 2146 | J33: 10578 | K33: 1916 | L33: 254 | M33: 235 | N33: 1197 | O33: 0 | P33: 22 | Q33: 10 | R33: =SUM(J33:Q33) -> 14212 | S33: =R33+I33+E33+D33 -> 41348 | T33: =IFERROR(VLOOKUP(B33,[1]月分析表!$A$9:$AT$120,44,0),0)+IFERROR(VLOOKUP(B33,[1]月分析表!$A$9:$AU$120,46,0),0) -> 0 | U33: =S33+C33+T33 -> 44202
B34: 610路 | C34: 4303 | D34: 25338 | E34: 1478 | F34: 3 | G34: 2496 | H34: 0 | I34: =SUM(F34:H34) -> 2499 | J34: 26654 | K34: 2510 | L34: 368 | M34: 293 | N34: 1280 | O34: 0 | P34: 7 | Q34: 12 | R34: =SUM(J34:Q34) -> 31124 | S34: =R34+I34+E34+D34 -> 60439 | T34: =IFERROR(VLOOKUP(B34,[1]月分析表!$A$9:$AT$120,44,0),0)+IFERROR(VLOOKUP(B34,[1]月分析表!$A$9:$AU$120,46,0),0) -> 0 | U34: =S34+C34+T34 -> 64742
B35: 618路 | C35: 305 | D35: 503 | E35: 14 | F35: 0 | G35: 0 | H35: 0 | I35: =SUM(F35:H35) -> 0 | J35: 240 | K35: 40 | L35: 0 | M35: 3 | N35: 25 | O35: 0 | P35: 0 | Q35: 0 | R35: =SUM(J35:Q35) -> 308 | S35: =R35+I35+E35+D35 -> 825 | T35: =IFERROR(VLOOKUP(B35,[1]月分析表!$A$9:$AT$120,44,0),0)+IFERROR(VLOOKUP(B35,[1]月分析表!$A$9:$AU$120,46,0),0) -> 0 | U35: =S35+C35+T35 -> 1130
B36: 619路 | C36: 273 | D36: 459 | E36: 14 | F36: 0 | G36: 2 | H36: 0 | I36: =SUM(F36:H36) -> 2 | J36: 254 | K36: 46 | L36: 0 | M36: 2 | N36: 23 | O36: 0 | P36: 0 | Q36: 0 | R36: =SUM(J36:Q36) -> 325 | S36: =R36+I36+E36+D36 -> 800 | T36: =IFERROR(VLOOKUP(B36,[1]月分析表!$A$9:$AT$120,44,0),0)+IFERROR(VLOOKUP(B36,[1]月分析表!$A$9:$AU$120,46,0),0) -> 0 | U36: =S36+C36+T36 -> 1073
B37: B247路 | C37: 4156 | D37: 22909 | E37: 893 | F37: 45 | G37: 1655 | H37: 0 | I37: =SUM(F37:H37) -> 1700 | J37: 5204 | K37: 996 | L37: 107 | M37: 194 | N37: 1157 | O37: 0 | P37: 2 | Q37: 2 | R37: =SUM(J37:Q37) -> 7662 | S37: =R37+I37+E37+D37 -> 33164 | T37: =IFERROR(VLOOKUP(B37,[1]月分析表!$A$9:$AT$120,44,0),0)+IFERROR(VLOOKUP(B37,[1]月分析表!$A$9:$AU$120,46,0),0) -> 0 | U37: =S37+C37+T37 -> 37320
B38: B292路 | C38: 6918 | D38: 90714 | E38: 2244 | F38: 59 | G38: 3923 | H38: 0 | I38: =SUM(F38:H38) -> 3982 | J38: 19200 | K38: 3141 | L38: 1199 | M38: 1304 | N38: 4582 | O38: 0 | P38: 44 | Q38: 20 | R38: =SUM(J38:Q38) -> 29490 | S38: =R38+I38+E38+D38 -> 126430 | T38: =IFERROR(VLOOKUP(B38,[1]月分析表!$A$9:$AT$120,44,0),0)+IFERROR(VLOOKUP(B38,[1]月分析表!$A$9:$AU$120,46,0),0) -> 393 | U38: =S38+C38+T38 -> 133741
B39: 18292路 | C39: 670 | D39: 10784 | E39: 155 | F39: 1 | G39: 294 | H39: 0 | I39: =SUM(F39:H39) -> 295 | J39: 1007 | K39: 224 | L39: 66 | M39: 172 | N39: 545 | O39: 0 | P39: 2 | Q39: 0 | R39: =SUM(J39:Q39) -> 2016 | S39: =R39+I39+E39+D39 -> 13250 | T39: =IFERROR(VLOOKUP(B39,[1]月分析表!$A$9:$AT$120,44,0),0)+IFERROR(VLOOKUP(B39,[1]月分析表!$A$9:$AU$120,46,0),0) -> 0 | U39: =S39+C39+T39 -> 13920
A40: 四车队 | B40: 26路 | C40: 40295 | D40: 223991 | E40: 9047 | F40: 2 | G40: 13369 | H40: 0 | I40: =SUM(F40:H40) -> 13371 | J40: 59789 | K40: 11256 | L40: 1685 | M40: 1243 | N40: 11314 | O40: 0 | P40: 74 | Q40: 53 | R40: =SUM(J40:Q40) -> 85414 | S40: =R40+I40+E40+D40 -> 331823 | T40: =IFERROR(VLOOKUP(B40,[1]月分析表!$A$9:$AT$120,44,0),0)+IFERROR(VLOOKUP(B40,[1]月分析表!$A$9:$AU$120,46,0),0) -> 4239 | U40: =S40+C40+T40 -> 376357
...

Sheet Sheet2

Sheet Sheet3
